Loading LIBD SLURM module for ldsc/1.0.1
Traceback (most recent call last):
  File "/dcs04/lieber/shared/statsgen/LDSC/base/scripts/ldsc.py", line 587, in <module>
    log = Logger(args.out+'.log')
  File "/dcs04/lieber/shared/statsgen/LDSC/base/scripts/ldsc.py", line 76, in __init__
    self.log_fh = open(fh, 'wb')
IOError: [Errno 2] No such file or directory: '/dcs04/lieber/marmaypag/spatialNac_LIBD4125/spatial_NAc/processed-data/19_sLDSC_old/10x_visium/sLDSC_coefficients/D1_islands/adhd.out.log'
Traceback (most recent call last):
  File "/dcs04/lieber/shared/statsgen/LDSC/base/scripts/ldsc.py", line 587, in <module>
    log = Logger(args.out+'.log')
  File "/dcs04/lieber/shared/statsgen/LDSC/base/scripts/ldsc.py", line 76, in __init__
    self.log_fh = open(fh, 'wb')
IOError: [Errno 2] No such file or directory: '/dcs04/lieber/marmaypag/spatialNac_LIBD4125/spatial_NAc/processed-data/19_sLDSC_old/10x_visium/sLDSC_coefficients/D1_islands/alcohol_ldscore.out.log'
Traceback (most recent call last):
  File "/dcs04/lieber/shared/statsgen/LDSC/base/scripts/ldsc.py", line 587, in <module>
    log = Logger(args.out+'.log')
  File "/dcs04/lieber/shared/statsgen/LDSC/base/scripts/ldsc.py", line 76, in __init__
    self.log_fh = open(fh, 'wb')
IOError: [Errno 2] No such file or directory: '/dcs04/lieber/marmaypag/spatialNac_LIBD4125/spatial_NAc/processed-data/19_sLDSC_old/10x_visium/sLDSC_coefficients/D1_islands/Alzheimer_ldscore.out.log'
Traceback (most recent call last):
  File "/dcs04/lieber/shared/statsgen/LDSC/base/scripts/ldsc.py", line 587, in <module>
    log = Logger(args.out+'.log')
  File "/dcs04/lieber/shared/statsgen/LDSC/base/scripts/ldsc.py", line 76, in __init__
    self.log_fh = open(fh, 'wb')
IOError: [Errno 2] No such file or directory: '/dcs04/lieber/marmaypag/spatialNac_LIBD4125/spatial_NAc/processed-data/19_sLDSC_old/10x_visium/sLDSC_coefficients/D1_islands/Alzheimer_ldscore2.out.log'
Traceback (most recent call last):
  File "/dcs04/lieber/shared/statsgen/LDSC/base/scripts/ldsc.py", line 587, in <module>
    log = Logger(args.out+'.log')
  File "/dcs04/lieber/shared/statsgen/LDSC/base/scripts/ldsc.py", line 76, in __init__
    self.log_fh = open(fh, 'wb')
IOError: [Errno 2] No such file or directory: '/dcs04/lieber/marmaypag/spatialNac_LIBD4125/spatial_NAc/processed-data/19_sLDSC_old/10x_visium/sLDSC_coefficients/D1_islands/Alzheimer_ldscore3.out.log'
Traceback (most recent call last):
  File "/dcs04/lieber/shared/statsgen/LDSC/base/scripts/ldsc.py", line 587, in <module>
    log = Logger(args.out+'.log')
  File "/dcs04/lieber/shared/statsgen/LDSC/base/scripts/ldsc.py", line 76, in __init__
    self.log_fh = open(fh, 'wb')
IOError: [Errno 2] No such file or directory: '/dcs04/lieber/marmaypag/spatialNac_LIBD4125/spatial_NAc/processed-data/19_sLDSC_old/10x_visium/sLDSC_coefficients/D1_islands/Anorexia_ldscore.out.log'
Traceback (most recent call last):
  File "/dcs04/lieber/shared/statsgen/LDSC/base/scripts/ldsc.py", line 587, in <module>
    log = Logger(args.out+'.log')
  File "/dcs04/lieber/shared/statsgen/LDSC/base/scripts/ldsc.py", line 76, in __init__
    self.log_fh = open(fh, 'wb')
IOError: [Errno 2] No such file or directory: '/dcs04/lieber/marmaypag/spatialNac_LIBD4125/spatial_NAc/processed-data/19_sLDSC_old/10x_visium/sLDSC_coefficients/D1_islands/AUD.EUR_META.NatMed2023.out.log'
Traceback (most recent call last):
  File "/dcs04/lieber/shared/statsgen/LDSC/base/scripts/ldsc.py", line 587, in <module>
    log = Logger(args.out+'.log')
  File "/dcs04/lieber/shared/statsgen/LDSC/base/scripts/ldsc.py", line 76, in __init__
    self.log_fh = open(fh, 'wb')
IOError: [Errno 2] No such file or directory: '/dcs04/lieber/marmaypag/spatialNac_LIBD4125/spatial_NAc/processed-data/19_sLDSC_old/10x_visium/sLDSC_coefficients/D1_islands/autism_ldscore.out.log'
Traceback (most recent call last):
  File "/dcs04/lieber/shared/statsgen/LDSC/base/scripts/ldsc.py", line 587, in <module>
    log = Logger(args.out+'.log')
  File "/dcs04/lieber/shared/statsgen/LDSC/base/scripts/ldsc.py", line 76, in __init__
    self.log_fh = open(fh, 'wb')
IOError: [Errno 2] No such file or directory: '/dcs04/lieber/marmaypag/spatialNac_LIBD4125/spatial_NAc/processed-data/19_sLDSC_old/10x_visium/sLDSC_coefficients/D1_islands/bmi_ldscore.out.log'
Traceback (most recent call last):
  File "/dcs04/lieber/shared/statsgen/LDSC/base/scripts/ldsc.py", line 587, in <module>
    log = Logger(args.out+'.log')
  File "/dcs04/lieber/shared/statsgen/LDSC/base/scripts/ldsc.py", line 76, in __init__
    self.log_fh = open(fh, 'wb')
IOError: [Errno 2] No such file or directory: '/dcs04/lieber/marmaypag/spatialNac_LIBD4125/spatial_NAc/processed-data/19_sLDSC_old/10x_visium/sLDSC_coefficients/D1_islands/bp3_ldscore.out.log'
Traceback (most recent call last):
  File "/dcs04/lieber/shared/statsgen/LDSC/base/scripts/ldsc.py", line 587, in <module>
    log = Logger(args.out+'.log')
  File "/dcs04/lieber/shared/statsgen/LDSC/base/scripts/ldsc.py", line 76, in __init__
    self.log_fh = open(fh, 'wb')
IOError: [Errno 2] No such file or directory: '/dcs04/lieber/marmaypag/spatialNac_LIBD4125/spatial_NAc/processed-data/19_sLDSC_old/10x_visium/sLDSC_coefficients/D1_islands/bp_ldscore.out.log'
Traceback (most recent call last):
  File "/dcs04/lieber/shared/statsgen/LDSC/base/scripts/ldsc.py", line 587, in <module>
    log = Logger(args.out+'.log')
  File "/dcs04/lieber/shared/statsgen/LDSC/base/scripts/ldsc.py", line 76, in __init__
    self.log_fh = open(fh, 'wb')
IOError: [Errno 2] No such file or directory: '/dcs04/lieber/marmaypag/spatialNac_LIBD4125/spatial_NAc/processed-data/19_sLDSC_old/10x_visium/sLDSC_coefficients/D1_islands/EA_aud_Jun07.txt_ldscore.out.log'
Traceback (most recent call last):
  File "/dcs04/lieber/shared/statsgen/LDSC/base/scripts/ldsc.py", line 587, in <module>
    log = Logger(args.out+'.log')
  File "/dcs04/lieber/shared/statsgen/LDSC/base/scripts/ldsc.py", line 76, in __init__
    self.log_fh = open(fh, 'wb')
IOError: [Errno 2] No such file or directory: '/dcs04/lieber/marmaypag/spatialNac_LIBD4125/spatial_NAc/processed-data/19_sLDSC_old/10x_visium/sLDSC_coefficients/D1_islands/epilepsyAll.out.log'
Traceback (most recent call last):
  File "/dcs04/lieber/shared/statsgen/LDSC/base/scripts/ldsc.py", line 587, in <module>
    log = Logger(args.out+'.log')
  File "/dcs04/lieber/shared/statsgen/LDSC/base/scripts/ldsc.py", line 76, in __init__
    self.log_fh = open(fh, 'wb')
IOError: [Errno 2] No such file or directory: '/dcs04/lieber/marmaypag/spatialNac_LIBD4125/spatial_NAc/processed-data/19_sLDSC_old/10x_visium/sLDSC_coefficients/D1_islands/epilepsyFocal.out.log'
Traceback (most recent call last):
  File "/dcs04/lieber/shared/statsgen/LDSC/base/scripts/ldsc.py", line 587, in <module>
    log = Logger(args.out+'.log')
  File "/dcs04/lieber/shared/statsgen/LDSC/base/scripts/ldsc.py", line 76, in __init__
    self.log_fh = open(fh, 'wb')
IOError: [Errno 2] No such file or directory: '/dcs04/lieber/marmaypag/spatialNac_LIBD4125/spatial_NAc/processed-data/19_sLDSC_old/10x_visium/sLDSC_coefficients/D1_islands/epilepsyGGE.out.log'
Traceback (most recent call last):
  File "/dcs04/lieber/shared/statsgen/LDSC/base/scripts/ldsc.py", line 587, in <module>
    log = Logger(args.out+'.log')
  File "/dcs04/lieber/shared/statsgen/LDSC/base/scripts/ldsc.py", line 76, in __init__
    self.log_fh = open(fh, 'wb')
IOError: [Errno 2] No such file or directory: '/dcs04/lieber/marmaypag/spatialNac_LIBD4125/spatial_NAc/processed-data/19_sLDSC_old/10x_visium/sLDSC_coefficients/D1_islands/GSCAN_AgeSmk_2022_ldscore.out.log'
Traceback (most recent call last):
  File "/dcs04/lieber/shared/statsgen/LDSC/base/scripts/ldsc.py", line 587, in <module>
    log = Logger(args.out+'.log')
  File "/dcs04/lieber/shared/statsgen/LDSC/base/scripts/ldsc.py", line 76, in __init__
    self.log_fh = open(fh, 'wb')
IOError: [Errno 2] No such file or directory: '/dcs04/lieber/marmaypag/spatialNac_LIBD4125/spatial_NAc/processed-data/19_sLDSC_old/10x_visium/sLDSC_coefficients/D1_islands/GSCAN_CigDay_2022_ldscore.out.log'
Traceback (most recent call last):
  File "/dcs04/lieber/shared/statsgen/LDSC/base/scripts/ldsc.py", line 587, in <module>
    log = Logger(args.out+'.log')
  File "/dcs04/lieber/shared/statsgen/LDSC/base/scripts/ldsc.py", line 76, in __init__
    self.log_fh = open(fh, 'wb')
IOError: [Errno 2] No such file or directory: '/dcs04/lieber/marmaypag/spatialNac_LIBD4125/spatial_NAc/processed-data/19_sLDSC_old/10x_visium/sLDSC_coefficients/D1_islands/GSCAN_DrnkWk_2022_ldscore.out.log'
Traceback (most recent call last):
  File "/dcs04/lieber/shared/statsgen/LDSC/base/scripts/ldsc.py", line 587, in <module>
    log = Logger(args.out+'.log')
  File "/dcs04/lieber/shared/statsgen/LDSC/base/scripts/ldsc.py", line 76, in __init__
    self.log_fh = open(fh, 'wb')
IOError: [Errno 2] No such file or directory: '/dcs04/lieber/marmaypag/spatialNac_LIBD4125/spatial_NAc/processed-data/19_sLDSC_old/10x_visium/sLDSC_coefficients/D1_islands/GSCAN_SmkCes_2022_ldscore.out.log'
Traceback (most recent call last):
  File "/dcs04/lieber/shared/statsgen/LDSC/base/scripts/ldsc.py", line 587, in <module>
    log = Logger(args.out+'.log')
  File "/dcs04/lieber/shared/statsgen/LDSC/base/scripts/ldsc.py", line 76, in __init__
    self.log_fh = open(fh, 'wb')
IOError: [Errno 2] No such file or directory: '/dcs04/lieber/marmaypag/spatialNac_LIBD4125/spatial_NAc/processed-data/19_sLDSC_old/10x_visium/sLDSC_coefficients/D1_islands/GSCAN_SmkInit_2022_ldscore.out.log'
