Loading LIBD SLURM module for ldsc/1.0.1
Traceback (most recent call last):
  File "/dcs04/lieber/shared/statsgen/LDSC/base/scripts/ldsc.py", line 587, in <module>
    log = Logger(args.out+'.log')
  File "/dcs04/lieber/shared/statsgen/LDSC/base/scripts/ldsc.py", line 76, in __init__
    self.log_fh = open(fh, 'wb')
IOError: [Errno 2] No such file or directory: '/dcs04/lieber/marmaypag/spatialNac_LIBD4125/spatial_NAc/processed-data/19_sLDSC_old/10x_visium/sLDSC_coefficients/Excitatory/height_ldscore.out.log'
Traceback (most recent call last):
  File "/dcs04/lieber/shared/statsgen/LDSC/base/scripts/ldsc.py", line 587, in <module>
    log = Logger(args.out+'.log')
  File "/dcs04/lieber/shared/statsgen/LDSC/base/scripts/ldsc.py", line 76, in __init__
    self.log_fh = open(fh, 'wb')
IOError: [Errno 2] No such file or directory: '/dcs04/lieber/marmaypag/spatialNac_LIBD4125/spatial_NAc/processed-data/19_sLDSC_old/10x_visium/sLDSC_coefficients/Excitatory/insomnia.out.log'
Traceback (most recent call last):
  File "/dcs04/lieber/shared/statsgen/LDSC/base/scripts/ldsc.py", line 587, in <module>
    log = Logger(args.out+'.log')
  File "/dcs04/lieber/shared/statsgen/LDSC/base/scripts/ldsc.py", line 76, in __init__
    self.log_fh = open(fh, 'wb')
IOError: [Errno 2] No such file or directory: '/dcs04/lieber/marmaypag/spatialNac_LIBD4125/spatial_NAc/processed-data/19_sLDSC_old/10x_visium/sLDSC_coefficients/Excitatory/intelligence.out.log'
Traceback (most recent call last):
  File "/dcs04/lieber/shared/statsgen/LDSC/base/scripts/ldsc.py", line 587, in <module>
    log = Logger(args.out+'.log')
  File "/dcs04/lieber/shared/statsgen/LDSC/base/scripts/ldsc.py", line 76, in __init__
    self.log_fh = open(fh, 'wb')
IOError: [Errno 2] No such file or directory: '/dcs04/lieber/marmaypag/spatialNac_LIBD4125/spatial_NAc/processed-data/19_sLDSC_old/10x_visium/sLDSC_coefficients/Excitatory/mdd2019edinburgh_ldscore.out.log'
Traceback (most recent call last):
  File "/dcs04/lieber/shared/statsgen/LDSC/base/scripts/ldsc.py", line 587, in <module>
    log = Logger(args.out+'.log')
  File "/dcs04/lieber/shared/statsgen/LDSC/base/scripts/ldsc.py", line 76, in __init__
    self.log_fh = open(fh, 'wb')
IOError: [Errno 2] No such file or directory: '/dcs04/lieber/marmaypag/spatialNac_LIBD4125/spatial_NAc/processed-data/19_sLDSC_old/10x_visium/sLDSC_coefficients/Excitatory/mdd_ex23andMe_ldscore.out.log'
Traceback (most recent call last):
  File "/dcs04/lieber/shared/statsgen/LDSC/base/scripts/ldsc.py", line 587, in <module>
    log = Logger(args.out+'.log')
  File "/dcs04/lieber/shared/statsgen/LDSC/base/scripts/ldsc.py", line 76, in __init__
    self.log_fh = open(fh, 'wb')
IOError: [Errno 2] No such file or directory: '/dcs04/lieber/marmaypag/spatialNac_LIBD4125/spatial_NAc/processed-data/19_sLDSC_old/10x_visium/sLDSC_coefficients/Excitatory/MDD_ldscore_PGC_UKB_23andme.out.log'
Traceback (most recent call last):
  File "/dcs04/lieber/shared/statsgen/LDSC/base/scripts/ldsc.py", line 587, in <module>
    log = Logger(args.out+'.log')
  File "/dcs04/lieber/shared/statsgen/LDSC/base/scripts/ldsc.py", line 76, in __init__
    self.log_fh = open(fh, 'wb')
IOError: [Errno 2] No such file or directory: '/dcs04/lieber/marmaypag/spatialNac_LIBD4125/spatial_NAc/processed-data/19_sLDSC_old/10x_visium/sLDSC_coefficients/Excitatory/MEGASTROKE.1.AS.EUR_ldscore.out.log'
Traceback (most recent call last):
  File "/dcs04/lieber/shared/statsgen/LDSC/base/scripts/ldsc.py", line 587, in <module>
    log = Logger(args.out+'.log')
  File "/dcs04/lieber/shared/statsgen/LDSC/base/scripts/ldsc.py", line 76, in __init__
    self.log_fh = open(fh, 'wb')
IOError: [Errno 2] No such file or directory: '/dcs04/lieber/marmaypag/spatialNac_LIBD4125/spatial_NAc/processed-data/19_sLDSC_old/10x_visium/sLDSC_coefficients/Excitatory/MEGASTROKE.2.AIS.EUR_ldscore.out.log'
Traceback (most recent call last):
  File "/dcs04/lieber/shared/statsgen/LDSC/base/scripts/ldsc.py", line 587, in <module>
    log = Logger(args.out+'.log')
  File "/dcs04/lieber/shared/statsgen/LDSC/base/scripts/ldsc.py", line 76, in __init__
    self.log_fh = open(fh, 'wb')
IOError: [Errno 2] No such file or directory: '/dcs04/lieber/marmaypag/spatialNac_LIBD4125/spatial_NAc/processed-data/19_sLDSC_old/10x_visium/sLDSC_coefficients/Excitatory/OUD_EA_MVP1_Mar12.out.log'
Traceback (most recent call last):
  File "/dcs04/lieber/shared/statsgen/LDSC/base/scripts/ldsc.py", line 587, in <module>
    log = Logger(args.out+'.log')
  File "/dcs04/lieber/shared/statsgen/LDSC/base/scripts/ldsc.py", line 76, in __init__
    self.log_fh = open(fh, 'wb')
IOError: [Errno 2] No such file or directory: '/dcs04/lieber/marmaypag/spatialNac_LIBD4125/spatial_NAc/processed-data/19_sLDSC_old/10x_visium/sLDSC_coefficients/Excitatory/OUD_EA_MVP1_MVP2_YP_SAGE_Mar12.out.log'
Traceback (most recent call last):
  File "/dcs04/lieber/shared/statsgen/LDSC/base/scripts/ldsc.py", line 587, in <module>
    log = Logger(args.out+'.log')
  File "/dcs04/lieber/shared/statsgen/LDSC/base/scripts/ldsc.py", line 76, in __init__
    self.log_fh = open(fh, 'wb')
IOError: [Errno 2] No such file or directory: '/dcs04/lieber/marmaypag/spatialNac_LIBD4125/spatial_NAc/processed-data/19_sLDSC_old/10x_visium/sLDSC_coefficients/Excitatory/OUD_EA_MVP2_Mar12.out.log'
Traceback (most recent call last):
  File "/dcs04/lieber/shared/statsgen/LDSC/base/scripts/ldsc.py", line 587, in <module>
    log = Logger(args.out+'.log')
  File "/dcs04/lieber/shared/statsgen/LDSC/base/scripts/ldsc.py", line 76, in __init__
    self.log_fh = open(fh, 'wb')
IOError: [Errno 2] No such file or directory: '/dcs04/lieber/marmaypag/spatialNac_LIBD4125/spatial_NAc/processed-data/19_sLDSC_old/10x_visium/sLDSC_coefficients/Excitatory/PASS_Type_2_Diabetes.sumstats.out.log'
Traceback (most recent call last):
  File "/dcs04/lieber/shared/statsgen/LDSC/base/scripts/ldsc.py", line 587, in <module>
    log = Logger(args.out+'.log')
  File "/dcs04/lieber/shared/statsgen/LDSC/base/scripts/ldsc.py", line 76, in __init__
    self.log_fh = open(fh, 'wb')
IOError: [Errno 2] No such file or directory: '/dcs04/lieber/marmaypag/spatialNac_LIBD4125/spatial_NAc/processed-data/19_sLDSC_old/10x_visium/sLDSC_coefficients/Excitatory/PD_ldscore.out.log'
Traceback (most recent call last):
  File "/dcs04/lieber/shared/statsgen/LDSC/base/scripts/ldsc.py", line 587, in <module>
    log = Logger(args.out+'.log')
  File "/dcs04/lieber/shared/statsgen/LDSC/base/scripts/ldsc.py", line 76, in __init__
    self.log_fh = open(fh, 'wb')
IOError: [Errno 2] No such file or directory: '/dcs04/lieber/marmaypag/spatialNac_LIBD4125/spatial_NAc/processed-data/19_sLDSC_old/10x_visium/sLDSC_coefficients/Excitatory/PTSD.out.log'
Traceback (most recent call last):
  File "/dcs04/lieber/shared/statsgen/LDSC/base/scripts/ldsc.py", line 587, in <module>
    log = Logger(args.out+'.log')
  File "/dcs04/lieber/shared/statsgen/LDSC/base/scripts/ldsc.py", line 76, in __init__
    self.log_fh = open(fh, 'wb')
IOError: [Errno 2] No such file or directory: '/dcs04/lieber/marmaypag/spatialNac_LIBD4125/spatial_NAc/processed-data/19_sLDSC_old/10x_visium/sLDSC_coefficients/Excitatory/scz_PGC2_CLOZUK_ldscore.out.log'
Traceback (most recent call last):
  File "/dcs04/lieber/shared/statsgen/LDSC/base/scripts/ldsc.py", line 587, in <module>
    log = Logger(args.out+'.log')
  File "/dcs04/lieber/shared/statsgen/LDSC/base/scripts/ldsc.py", line 76, in __init__
    self.log_fh = open(fh, 'wb')
IOError: [Errno 2] No such file or directory: '/dcs04/lieber/marmaypag/spatialNac_LIBD4125/spatial_NAc/processed-data/19_sLDSC_old/10x_visium/sLDSC_coefficients/Excitatory/scz_PGC3_ldscore.out.log'
Traceback (most recent call last):
  File "/dcs04/lieber/shared/statsgen/LDSC/base/scripts/ldsc.py", line 587, in <module>
    log = Logger(args.out+'.log')
  File "/dcs04/lieber/shared/statsgen/LDSC/base/scripts/ldsc.py", line 76, in __init__
    self.log_fh = open(fh, 'wb')
IOError: [Errno 2] No such file or directory: '/dcs04/lieber/marmaypag/spatialNac_LIBD4125/spatial_NAc/processed-data/19_sLDSC_old/10x_visium/sLDSC_coefficients/Excitatory/smoking_ldscore.out.log'
Traceback (most recent call last):
  File "/dcs04/lieber/shared/statsgen/LDSC/base/scripts/ldsc.py", line 587, in <module>
    log = Logger(args.out+'.log')
  File "/dcs04/lieber/shared/statsgen/LDSC/base/scripts/ldsc.py", line 76, in __init__
    self.log_fh = open(fh, 'wb')
IOError: [Errno 2] No such file or directory: '/dcs04/lieber/marmaypag/spatialNac_LIBD4125/spatial_NAc/processed-data/19_sLDSC_old/10x_visium/sLDSC_coefficients/Excitatory/stroke2022any.out.log'
Traceback (most recent call last):
  File "/dcs04/lieber/shared/statsgen/LDSC/base/scripts/ldsc.py", line 587, in <module>
    log = Logger(args.out+'.log')
  File "/dcs04/lieber/shared/statsgen/LDSC/base/scripts/ldsc.py", line 76, in __init__
    self.log_fh = open(fh, 'wb')
IOError: [Errno 2] No such file or directory: '/dcs04/lieber/marmaypag/spatialNac_LIBD4125/spatial_NAc/processed-data/19_sLDSC_old/10x_visium/sLDSC_coefficients/Excitatory/UKB_460K.cov_EDU_YEARS.sumstats.out.log'
Traceback (most recent call last):
  File "/dcs04/lieber/shared/statsgen/LDSC/base/scripts/ldsc.py", line 587, in <module>
    log = Logger(args.out+'.log')
  File "/dcs04/lieber/shared/statsgen/LDSC/base/scripts/ldsc.py", line 76, in __init__
    self.log_fh = open(fh, 'wb')
IOError: [Errno 2] No such file or directory: '/dcs04/lieber/marmaypag/spatialNac_LIBD4125/spatial_NAc/processed-data/19_sLDSC_old/10x_visium/sLDSC_coefficients/Excitatory/UKB_460K.mental_NEUROTICISM.sumstats.out.log'
